<?xml version="1.0"?>
<robot name="end_effectors" xmlns:xacro="http://www.ros.org/wiki/xacro">
    <!-- istanziare la macro-->
    
    

    



    <xacro:macro name="wiring_gripper" params="prefix parent rpy:='0 0 0' xyz:='0 0 0'"> <!-- *origin-->

        <link name="${prefix}robotiq_hand">
            <inertial>
            <origin xyz="0.056379 4.9794E-05 0.00020009" rpy="0 0 0" />
            <mass value="2.6404" />
            <inertia
                ixx="0.0014834"
                ixy="-3.7391E-06"
                ixz="3.3528E-06"
                iyy="0.002045"
                iyz="8.3983E-06"
                izz="0.0020565" />
            </inertial>
            <visual>
            <origin xyz="0 0 0" rpy="0 0 0" />
            <geometry>
                <mesh filename="package://robotiq_hand_e/meshes/wiring_gripper.STL" />
            </geometry>
            <material name="">
                <color rgba="0.31765 0.24706 0.20784 1" />
            </material>
            </visual>
            <collision>
            <origin xyz="0 0 0" rpy="0 0 0" />
            <geometry>
                <mesh filename="package://robotiq_hand_e/meshes/wiring_gripper.STL" />
            </geometry>
            </collision>
        </link>

        <joint name="${prefix}gripper_joint" type="fixed">
            <!-- <xacro:insert_block name="origin" /> -->
            <origin xyz="${xyz}" rpy="${rpy}"/>
            <parent link="${parent}"/>
            <child  link="${prefix}robotiq_hand"/>
        </joint>

        <link name="${prefix}finger_left">
            <inertial>
            <origin xyz="-0.041146 0.063717 0.0094944" rpy="0 0 0" />
            <mass value="0.19486" />
            <inertia
                ixx="4.9675E-05"
                ixy="2.4802E-05"
                ixz="-4.8356E-07"
                iyy="2.7862E-05"
                iyz="2.8798E-06"
                izz="7.1379E-05" />
            </inertial>
            <visual>
            <origin xyz="0 0 0" rpy="0 0 0" />
            <geometry>
                <mesh filename="package://robotiq_hand_e/meshes/finger_left.STL" />
            </geometry>
            <material name="">
                <color rgba="0.64706 0.61961 0.58824 1" />
            </material>
            </visual>
            <collision>
            <origin xyz="0 0 0" rpy="0 0 0" />
            <geometry>
                <mesh filename="package://robotiq_hand_e/meshes/finger_left.STL" />
            </geometry>
            </collision>
        </link>
      
        <joint name="${prefix}bl_to_leftFinger" type="prismatic">
            <origin xyz="0.1133 0 0" rpy="0 0.87266 -1.5708" />
            <parent link="${prefix}robotiq_hand" />
            <child link="${prefix}finger_left" />
            <axis xyz="0 0 1" />
            <limit lower="0" upper="0.0225" effort="185" velocity="150" /> <!-- Forza di presa: 20-185N, Velocità di chiusura: 20-150mm/s --> 
        </joint>

        <link name="${prefix}finger_right">
            <inertial>
                <origin xyz="0.040691 0.063717 0.0095363" rpy="0 0 0" />
                <mass value="0.19486" />
                <inertia
                ixx="4.9675E-05"
                ixy="-2.4835E-05"
                ixz="4.5546E-07"
                iyy="2.7862E-05"
                iyz="2.8798E-06"
                izz="7.1379E-05" />
            </inertial>
            <visual>
                <origin xyz="0 0 0" rpy="0 0 0" />
                <geometry>
                <mesh filename="package://robotiq_hand_e/meshes/finger_right.STL" />
                </geometry>
                <material name="">
                <color rgba="0.64706 0.61961 0.58824 1" />
                </material>
            </visual>
            <collision>
                <origin xyz="0 0 0" rpy="0 0 0" />
                <geometry>
                <mesh filename="package://robotiq_hand_e/meshes/finger_right.STL" />
                </geometry>


                <surface>
                    <friction>
                    <ode>
                        <mu>0.9</mu>
                        <mu2>0.9</mu2>
                    </ode>
                    </friction>
                    <contact>
                    <ode>
                        <min_depth>0.003</min_depth>
                    </ode>
                    </contact>
                </surface>
            </collision>
        </link>

        <!-- <joint name="${prefix}leftFinger_to_rightFinger" type="prismatic">
            <origin xyz="0.1133 0 0" rpy="0 4.01266 -1.5708" />
            <parent link="${prefix}robotiq_hand" />
            <child link="${prefix}finger_right" />
            <axis xyz="0 0 1" />
            <limit lower="0" upper="0.0225" effort="185" velocity="150" />
            <mimic joint="${prefix}bl_to_leftFinger" multiplier="1" offset="0" />
        </joint> -->

        <joint name="${prefix}leftFinger_to_rightFinger" type="prismatic">
            <origin xyz="1E-05 0 0" rpy="3.1416 0 3.1416" />
            <parent link="${prefix}finger_left" />
            <child link="${prefix}finger_right" />
            <axis xyz="0 0 1" />
            <limit lower="0.0" upper="0.045" effort="185" velocity="150" />
        </joint>

        <link name="${prefix}finger_tip"/>
        
        <joint name="${prefix}rightFinger_to_tip" type="fixed">
            <origin rpy="${pi/2} -0.785 ${pi/2}" xyz="0.2655  0.05585 0.06655"/>
            <parent link="${prefix}robotiq_hand"/>
            <child link="${prefix}finger_tip"/>
        </joint>

    </xacro:macro>

    <!-- <link name="world"/>
    <xacro:wiring_gripper prefix="pippo" parent="world" /> -->

    



</robot>